<?xml version="1.0"?>
<robot name="BloodSport">
  <link name="base_link">
    <visual>
      <geometry>
        <cylinder length="0.0762" radius="0.406"/>
      </geometry>
    </visual>
    <collision>
      <geometry>
        <cylinder length="0.0762" radius="0.406"/>
      </geometry>
    </collision>
    <inertial>
      <mass value="90"/>
      <inertia ixx="3.8" ixy="0.0" ixz="0.0" iyy="3.8" iyz="0.0" izz="7.4"/>
    </inertial>
  </link>
  <link name="weapon">
    <visual>
      <origin rpy="0 0 0" xyz="0 0.2 0.1"/>
      <geometry>
        <box size="1.22 0.15 0.019"/>
      </geometry>
    </visual>
    <collision>
      <origin rpy="0 0 0" xyz="0 0.2 0.1"/>
      <geometry>
        <box size="1.22 0.15 0.019"/>
      </geometry>
    </collision>
    <inertial>
      <origin rpy="0 0 0" xyz="0 0.2 0.1"/>
      <mass value="2.393E+01"/>
      <inertia ixx="0.05556" ixy="-4.878E-15" ixz="-5.582E-3" iyy="2.474" iyz="-7.068E-18" izz="2.420"/>
    </inertial>
  </link>

  <joint name="base_to_weapon" type="continuous">
    <parent link="base_link"/>
    <child link="weapon"/>
    <origin xyz="0 0 0" rpy="0 0 0"/>
    <axis xyz="0 0 1"/>

    <limit effort="50" velocity="150.0"/>
  </joint>


  <transmission name="spinner">
    <type>transmission_interface/SimpleTransmission</type>
    <actuator name="$scorpion">
      <mechanicalReduction>1</mechanicalReduction>
    </actuator>
    <joint name="base_to_weapon">
      <hardwareInterface>VelocityJointInterface</hardwareInterface>
    </joint>
  </transmission>






  <gazebo>
    <plugin name="gazebo_ros_control" filename="libgazebo_ros_control.so">
      <robotNamespace>/</robotNamespace>
    </plugin>
  </gazebo>
</robot>